Workbook

Sheet cover
T2: Financial Analysis & DuPont Modeling | 2020 – 2025
B4: Ferrari N.V. (NYSE/EXM: RACE) — 3-Statement Financial Analysis & DuPont Analysis
B5: 6-Year Historical Performance (2020 – 2025) under IFRS & CFI Valuation Standards
B8: TABLE OF CONTENTS | O8: ANALYST PROFILE
A9: 1 | B9: Financial Statements (Standardized 3-Statement Model) | I9: 5 | J9: Profitability | O9: Prepared By: Mohamed Slama
A10: 2 | B10: Ratio Calculations (Liquidity, Turnover & Leverage Ratios) | I10: 6 | J10: Utilization | O10: Framework: Corporate Finance Institute (CFI) Standards
A11: 3 | B11: 3-Step DuPont Pyramid (ROE Deconstruction) | I11: 7 | J11: Leverage | O11: LinkedIn: | P11: https://www.linkedin.com/in/m-salama1996/
A12: 4 | B12: 5-Step DuPont Pyramid (Extended Operating & Burden Analysis) | I12: 8 | J12: Growth | O12: Completion Date: October 2026
O14: KEY MODELING HIGHLIGHTS & OFFICIAL TIE-OUTS
O15: Depreciation & Amortization Isolation: Separated non-cash industrial depreciation from COGS and R&D according to Note disclosures, isolating cash gross profit and establishing an exact EBITDA tie-out.
O17: Debt Structure & Capital Segmentation: Disaggregated interest-bearing liabilities into short-term borrowings and long-term debt (via Notes 24 & 27), enabling a precise reconciliation between Invested Capital and Net Operating Assets while perfectly matching Ferrari's reported Net Debt.
O20: Full Alignment with Official 2025 Results: The model achieves exact consistency with Ferrari’s FY 2025 Investor Presentation:
O21: Net Revenues: €7.15B vs. €7.1B reported (+7.0% YoY Growth).
O22: EBITDA: €2.77B at an exact 38.8% margin.
O23: Leverage: Net Debt to EBITDA reduced to 0.5x, perfectly matching disclosed leverage trends.
O24: Negative Cash Conversion Cycle (CCC): Identified and modeled Ferrari’s luxury operational working capital dynamics, sustaining negative to ultra-lean cash cycles driven by dealer prepayments and extended payable windows.
O27: Project Roadmap (Next Phases):
O28: Phase 1 (Completed): Ferrari N.V. Standalone In-depth Financial Model & DuPont Pyramid.
O29: Phase 2 (In-Progress): Peer Group Benchmarking against Luxury & Ultra-Luxury Automakers (Porsche AG, Aston Martin Lagonda).
O30: Phase 3 (Upcoming): Integrated DCF (Discounted Cash Flow) Valuation Model based on midterm corporate guidance.

Sheet Financial Statements
K1: by/ m.salama
B3: INCOME STATEMENT
B5: All figures in EUR thousand | F5: 2020 | G5: 2021 | H5: 2022 | I5: 2023 | J5: 2024 | K5: 2025
B8: Net revenues | F8: 3459790 | G8: 4270894 | H8: 5095254 | I8: 5970146 | J8: 6676668 | K8: 7145768
B9: Cost of sales | F9: -1686324 | G9: -2080613 | H9: -2648953 | I9: -2995877 | J9: -3329483 | K9: -3452971
B10: Depreciation | F10: 217952 | G10: 230097 | H10: 259849 | I10: 290204 | J10: 299638 | K10: 298734
B11: Gross profit | F11: =SUM(F8:F10) -> 1991418 | G11: =SUM(G8:G10) -> 2420378 | H11: =SUM(H8:H10) -> 2706150 | I11: =SUM(I8:I10) -> 3264473 | J11: =SUM(J8:J10) -> 3646823 | K11: =SUM(K8:K10) -> 3991531
B14: SG&A | F14: -336126 | G14: -348024 | H14: -427974 | I14: -462580 | J14: -561144 | K14: -642490
B15: R&D | F15: -707385 | G15: -768104 | H15: -775572 | I15: -881559 | J15: -894092 | K15: -918861
B16: Amortization | F16: 208685 | G16: 225892 | H16: 286376 | I16: 372101 | J16: 367139 | K16: 363202
B17: Other expenses, net | F17: -18475 | G17: -5561 | H17: -21548 | I17: -18898 | J17: -12443 | K17: -34302
B18: Result from investments | F18: 4647 | G18: 6896 | H18: 6175 | I18: 6137 | J18: 8245 | K18: 12572
B19: EBITDA | F19: =SUM(F11:F18) -> 1142764 | G19: =SUM(G11:G18) -> 1531477 | H19: =SUM(H11:H18) -> 1773607 | I19: =SUM(I11:I18) -> 2279674 | J19: =SUM(J11:J18) -> 2554528 | K19: =SUM(K11:K18) -> 2771652
B22: Depreciation | F22: -426637 | G22: -455989 | H22: -546225 | I22: -662305 | J22: -666777 | K22: -661937
B23: EBIT | F23: =SUM(F19:F22) -> 716127 | G23: =SUM(G19:G22) -> 1075488 | H23: =SUM(H19:H22) -> 1227382 | I23: =SUM(I19:I22) -> 1617369 | J23: =SUM(J19:J22) -> 1887751 | K23: =SUM(K19:K22) -> 2109715
B26: Interest Expense | F26: -49092 | G26: -76256 | H26: -133474 | I26: -147334 | J26: -145895 | K26: -214226
B27: Interest Income | F27: 0 | G27: 42999 | H27: 83858 | I27: 132319 | J27: 147100 | K27: 168145
B28: EBT | F28: =SUM(F23:F27) -> 667035 | G28: =SUM(G23:G27) -> 1042231 | H28: =SUM(H23:H27) -> 1177766 | I28: =SUM(I23:I27) -> 1602354 | J28: =SUM(J23:J27) -> 1888956 | K28: =SUM(K23:K27) -> 2063634
B31: Provision for Taxes | F31: -58155 | G31: -209095 | H31: -238472 | I31: -344897 | J31: -363043 | K31: -464119
B34: Net Income | F34: =SUM(F28:F33) -> 608880 | G34: =SUM(G28:G33) -> 833136 | H34: =SUM(H28:H33) -> 939294 | I34: =SUM(I28:I33) -> 1257457 | J34: =SUM(J28:J33) -> 1525913 | K34: =SUM(K28:K33) -> 1599515
B38: STATEMENT OF CASH FLOWS
B40: All figures in EUR thousand | F40: 2020 | G40: 2021 | H40: 2022 | I40: 2023 | J40: 2024 | K40: 2025
B44: Cash From Operating
B45: Net profit | F45: 608880 | G45: 833136 | H45: 939294 | I45: 1257457 | J45: 1525913 | K45: 1599516
B46: Income tax expense | F46: 58155 | G46: 209095 | H46: 238472 | I46: 344897 | J46: 363043 | K46: 464119
B47: Amortization and depreciation | F47: 426637 | G47: 455989 | H47: 546225 | I47: 662305 | J47: 666777 | K47: 661937
B48: Net Finance costs / (income) | F48: 49092 | G48: 33257 | H48: 49616 | I48: 15015 | J48: -1205 | K48: 46081
B49: Other non-cash & working capital changes | F49: -213502 | G49: -139652 | H49: -65575 | I49: -270574 | J49: -218086 | K49: -36793
B50: Income tax paid | F50: -91051 | G50: -109099 | H50: -304692 | I50: -292463 | J50: -409786 | K50: -385554
B51: Subtotal | F51: =SUM(F45:F50) -> 838211 | G51: =SUM(G45:G50) -> 1282726 | H51: =SUM(H45:H50) -> 1403340 | I51: =SUM(I45:I50) -> 1716637 | J51: =SUM(J45:J50) -> 1926656 | K51: =SUM(K45:K50) -> 2349306
B53: Cash From Invisting
B54: Investments in property, plant and equipment (CapEx PPE) | F54: -357018 | G54: -352316 | H54: -347725 | I54: -381762 | J54: -482277 | K54: -485210
B55: Investments in intangible assets (CapEx Intangibles) | F55: -351978 | G55: -384827 | H55: -456894 | I55: -487148 | J55: -506874 | K55: -457976
B56: Other investing proceeds / (investments) | F56: 969 | G56: 4405 | H56: -789 | I56: 2458 | J56: 2041 | K56: -952
B57: Subtotal | F57: =SUM(F54:F56) -> -708027 | G57: =SUM(G54:G56) -> -732738 | H57: =SUM(H54:H56) -> -805408 | I57: =SUM(I54:I56) -> -866452 | J57: =SUM(J54:J56) -> -987110 | K57: =SUM(K54:K56) -> -944138
B60: Cash From Financing
B61: Dividends paid to owners and non-controlling | F61: -211029 | G61: -161455 | H61: -251788 | I61: -333521 | J61: -444706 | K61: -534155
B62: Share repurchases | F62: -129793 | G62: -230899 | H62: -396522 | I62: -460629 | J62: -581084 | K62: -785329
B63: Net change in borrowings, notes, securitizations & leases | F63: 680505 | G63: -187318 | H63: 94750 | I63: -315257 | J63: 701029 | K63: -347673
B64: Subtotal | F64: =SUM(F61:F63) -> 339683 | G64: =SUM(G61:G63) -> -579672 | H64: =SUM(H61:H63) -> -553560 | I64: =SUM(I61:I63) -> -1109407 | J64: =SUM(J61:J63) -> -324761 | K64: =SUM(K61:K63) -> -1667157
...

Sheet Ratio Calculations
R1: by/ m.salama
B3: Profitability and Return Ratios
B5: All figures in EUR thousand | F5: 2020 | G5: 2021 | H5: 2022 | I5: 2023 | J5: 2024 | K5: 2025 | M5: =+F5 -> 2020 | N5: =+G5 -> 2021 | O5: =+H5 -> 2022 | P5: =+I5 -> 2023 | Q5: =+J5 -> 2024 | R5: =+K5 -> 2025
B8: Return on Equity | C8: = | D8: Net Income | E8: = | F8: ='Financial Statements'!F34 -> 608880 | G8: ='Financial Statements'!G34 -> 833136 | H8: ='Financial Statements'!H34 -> 939294 | I8: ='Financial Statements'!I34 -> 1257457 | J8: ='Financial Statements'!J34 -> 1525913 | K8: ='Financial Statements'!K34 -> 1599515 | L8: = | M8: =IF(F9=0,,F8/F9) -> 0.34030776 | N8: =IF(G9=0,,G8/G9) -> 0.37674323 | O8: =IF(H9=0,,H8/H9) -> 0.36092169 | P8: =IF(I9=0,,I8/I9) -> 0.40951214 | Q8: =IF(J9=0,,J8/J9) -> 0.43065495 | R8: =IF(K9=0,,K8/K9) -> 0.40858759
D9: Equity | F9: ='Financial Statements'!F106 -> 1789204 | G9: ='Financial Statements'!G106 -> 2211416 | H9: ='Financial Statements'!H106 -> 2602487 | I9: ='Financial Statements'!I106 -> 3070622 | J9: ='Financial Statements'!J106 -> 3543238 | K9: ='Financial Statements'!K106 -> 3914742
B11: Return on Assets | C11: = | D11: Net Income | E11: = | F11: =F8 -> 608880 | G11: =G8 -> 833136 | H11: =H8 -> 939294 | I11: =I8 -> 1257457 | J11: =J8 -> 1525913 | K11: =K8 -> 1599515 | L11: = | M11: =IF(F12=0,,F11/F12) -> 0.097233381 | N11: =IF(G12=0,,G11/G12) -> 0.12138638 | O11: =IF(H12=0,,H11/H12) -> 0.12095228 | P11: =IF(I12=0,,I11/I12) -> 0.15618038 | Q11: =IF(J12=0,,J11/J12) -> 0.16067069 | R11: =IF(K12=0,,K11/K12) -> 0.16612552
D12: Total Assets | F12: ='Financial Statements'!F99 -> 6262047 | G12: ='Financial Statements'!G99 -> 6863505 | H12: ='Financial Statements'!H99 -> 7765823 | I12: ='Financial Statements'!I99 -> 8051312 | J12: ='Financial Statements'!J99 -> 9497146 | K12: ='Financial Statements'!K99 -> 9628352
B14: Return on Net Assets | C14: = | D14: Net Income | E14: = | F14: =F11 -> 608880 | G14: =G11 -> 833136 | H14: =H11 -> 939294 | I14: =I11 -> 1257457 | J14: =J11 -> 1525913 | K14: =K11 -> 1599515 | L14: = | M14: =IF(F15=0,,F14/F15) -> 0.1932006 | N14: =IF(G15=0,,G14/G15) -> 0.23822392 | O14: =IF(H15=0,,H14/H15) -> 0.23334381 | P14: =IF(I15=0,,I14/I15) -> 0.28411797 | Q14: =IF(J15=0,,J14/J15) -> 0.29612635 | R14: =IF(K15=0,,K14/K15) -> 0.3000262
D15: PP&E plus Net Working Capital | F15: ='Financial Statements'!F152 -> 3151543 | G15: ='Financial Statements'!G152 -> 3497281 | H15: ='Financial Statements'!H152 -> 4025365 | I15: ='Financial Statements'!I152 -> 4425827 | J15: ='Financial Statements'!J152 -> 5152912 | K15: ='Financial Statements'!K152 -> 5331251
B17: Return on Invested Capital | C17: = | D17: NOPAT | E17: = | F17: ='Financial Statements'!F136 -> 653691.95 | G17: ='Financial Statements'!G136 -> 859720.9 | H17: ='Financial Statements'!H136 -> 978863.84 | I17: ='Financial Statements'!I136 -> 1269240.1 | J17: ='Financial Statements'!J136 -> 1524939.6 | K17: ='Financial Statements'!K136 -> 1635232.2 | L17: = | M17: =IF(F18=0,,F17/F18) -> 0.20741965 | N17: =IF(G18=0,,G17/G18) -> 0.24582551 | O17: =IF(H18=0,,H17/H18) -> 0.24317393 | P17: =IF(I18=0,,I17/I18) -> 0.28678033 | Q17: =IF(J18=0,,J17/J18) -> 0.29593744 | R17: =IF(K18=0,,K17/K18) -> 0.3067258
D18: Invested Capital | F18: ='Financial Statements'!F145 -> 3151543 | G18: ='Financial Statements'!G145 -> 3497281 | H18: ='Financial Statements'!H145 -> 4025365 | I18: ='Financial Statements'!I145 -> 4425827 | J18: ='Financial Statements'!J145 -> 5152912 | K18: ='Financial Statements'!K145 -> 5331251
B20: Gross Margin | C20: = | D20: Gross Profit | E20: = | F20: ='Financial Statements'!F11 -> 1991418 | G20: ='Financial Statements'!G11 -> 2420378 | H20: ='Financial Statements'!H11 -> 2706150 | I20: ='Financial Statements'!I11 -> 3264473 | J20: ='Financial Statements'!J11 -> 3646823 | K20: ='Financial Statements'!K11 -> 3991531 | L20: = | M20: =IF(F21=0,,F20/F21) -> 0.57558927 | N20: =IF(G21=0,,G20/G21) -> 0.5667146 | O20: =IF(H21=0,,H20/H21) -> 0.53111189 | P20: =IF(I21=0,,I20/I21) -> 0.54679953 | Q20: =IF(J21=0,,J20/J21) -> 0.54620403 | R20: =IF(K21=0,,K20/K21) -> 0.5585867
D21: =+D30 -> Revenue | F21: ='Financial Statements'!F8 -> 3459790 | G21: ='Financial Statements'!G8 -> 4270894 | H21: ='Financial Statements'!H8 -> 5095254 | I21: ='Financial Statements'!I8 -> 5970146 | J21: ='Financial Statements'!J8 -> 6676668 | K21: ='Financial Statements'!K8 -> 7145768
B23: SG&A % of Revenue | C23: = | D23: SG&A | E23: = | F23: =-'Financial Statements'!F14 -> 336126 | G23: =-'Financial Statements'!G14 -> 348024 | H23: =-'Financial Statements'!H14 -> 427974 | I23: =-'Financial Statements'!I14 -> 462580 | J23: =-'Financial Statements'!J14 -> 561144 | K23: =-'Financial Statements'!K14 -> 642490 | L23: = | M23: =IF(F24=0,,F23/F24) -> 0.097152139 | N23: =IF(G24=0,,G23/G24) -> 0.081487389 | O23: =IF(H24=0,,H23/H24) -> 0.083994635 | P23: =IF(I24=0,,I23/I24) -> 0.077482192 | Q23: =IF(J24=0,,J23/J24) -> 0.084045515 | R23: =IF(K24=0,,K23/K24) -> 0.089911959
D24: =+D21 -> Revenue | F24: =F21 -> 3459790 | G24: =G21 -> 4270894 | H24: =H21 -> 5095254 | I24: =I21 -> 5970146 | J24: =J21 -> 6676668 | K24: =K21 -> 7145768
B26: Other Operating Expenses % of Revenue | C26: = | D26: Other Operating Expenses | E26: = | F26: =F20-F23-F29 -> 512528 | G26: =G20-G23-G29 -> 540877 | H26: =H20-H23-H29 -> 504569 | I26: =I20-I23-I29 -> 522219 | J26: =J20-J23-J29 -> 531151 | K26: =K20-K23-K29 -> 577389 | L26: = | M26: =IF(F27=0,,F26/F27) -> 0.14813847 | N26: =IF(G27=0,,G26/G27) -> 0.12664257 | O26: =IF(H27=0,,H26/H27) -> 0.099027252 | P26: =IF(I27=0,,I26/I27) -> 0.08747173 | Q26: =IF(J27=0,,J26/J27) -> 0.079553304 | R26: =IF(K27=0,,K26/K27) -> 0.080801532
D27: =+D24 -> Revenue | F27: =F24 -> 3459790 | G27: =G24 -> 4270894 | H27: =H24 -> 5095254 | I27: =I24 -> 5970146 | J27: =J24 -> 6676668 | K27: =K24 -> 7145768
B29: EBITDA Margin | C29: = | D29: EBITDA | E29: = | F29: ='Financial Statements'!F19 -> 1142764 | G29: ='Financial Statements'!G19 -> 1531477 | H29: ='Financial Statements'!H19 -> 1773607 | I29: ='Financial Statements'!I19 -> 2279674 | J29: ='Financial Statements'!J19 -> 2554528 | K29: ='Financial Statements'!K19 -> 2771652 | L29: = | M29: =IF(F30=0,,F29/F30) -> 0.33029866 | N29: =IF(G30=0,,G29/G30) -> 0.35858464 | O29: =IF(H30=0,,H29/H30) -> 0.34809001 | P29: =IF(I30=0,,I29/I30) -> 0.3818456 | Q29: =IF(J30=0,,J29/J30) -> 0.38260522 | R29: =IF(K30=0,,K29/K30) -> 0.38787321
D30: =+D37 -> Revenue | F30: =F27 -> 3459790 | G30: =G27 -> 4270894 | H30: =H27 -> 5095254 | I30: =I27 -> 5970146 | J30: =J27 -> 6676668 | K30: =K27 -> 7145768
B31: Check | M31: =IF(ABS(M20-M23-M26-M29)<0.0001,"OK","Error") -> OK | N31: =IF(ABS(N20-N23-N26-N29)<0.0001,"OK","Error") -> OK | O31: =IF(ABS(O20-O23-O26-O29)<0.0001,"OK","Error") -> OK | P31: =IF(ABS(P20-P23-P26-P29)<0.0001,"OK","Error") -> OK | Q31: =IF(ABS(Q20-Q23-Q26-Q29)<0.0001,"OK","Error") -> OK | R31: =IF(ABS(R20-R23-R26-R29)<0.0001,"OK","Error") -> OK
B33: Depreciation % of Revenue | C33: = | D33: Depreciation | E33: = | F33: =-'Financial Statements'!F22 -> 426637 | G33: =-'Financial Statements'!G22 -> 455989 | H33: =-'Financial Statements'!H22 -> 546225 | I33: =-'Financial Statements'!I22 -> 662305 | J33: =-'Financial Statements'!J22 -> 666777 | K33: =-'Financial Statements'!K22 -> 661937 | L33: = | M33: =IF(F34=0,,F33/F34) -> 0.12331298 | N33: =IF(G34=0,,G33/G34) -> 0.10676664 | O33: =IF(H34=0,,H33/H34) -> 0.1072027 | P33: =IF(I34=0,,I33/I34) -> 0.11093615 | Q33: =IF(J34=0,,J33/J34) -> 0.09986673 | R33: =IF(K34=0,,K33/K34) -> 0.09263343
D34: =+D21 -> Revenue | F34: =F30 -> 3459790 | G34: =G30 -> 4270894 | H34: =H30 -> 5095254 | I34: =I30 -> 5970146 | J34: =J30 -> 6676668 | K34: =K30 -> 7145768
B36: EBIT Margin | C36: = | D36: EBIT | E36: = | F36: ='Financial Statements'!F23 -> 716127 | G36: ='Financial Statements'!G23 -> 1075488 | H36: ='Financial Statements'!H23 -> 1227382 | I36: ='Financial Statements'!I23 -> 1617369 | J36: ='Financial Statements'!J23 -> 1887751 | K36: ='Financial Statements'!K23 -> 2109715 | L36: = | M36: =IF(F37=0,,F36/F37) -> 0.20698568 | N36: =IF(G37=0,,G36/G37) -> 0.251818 | O36: =IF(H37=0,,H36/H37) -> 0.2408873 | P36: =IF(I37=0,,I36/I37) -> 0.27090946 | Q36: =IF(J37=0,,J36/J37) -> 0.28273849 | R36: =IF(K37=0,,K36/K37) -> 0.29523978
D37: =+D45 -> Revenue | F37: =F34 -> 3459790 | G37: =G34 -> 4270894 | H37: =H34 -> 5095254 | I37: =I34 -> 5970146 | J37: =J34 -> 6676668 | K37: =K34 -> 7145768
B38: Check | M38: =IF(ABS(M29-M33-M36)<0.0001,"OK","Error") -> OK | N38: =IF(ABS(N29-N33-N36)<0.0001,"OK","Error") -> OK | O38: =IF(ABS(O29-O33-O36)<0.0001,"OK","Error") -> OK | P38: =IF(ABS(P29-P33-P36)<0.0001,"OK","Error") -> OK | Q38: =IF(ABS(Q29-Q33-Q36)<0.0001,"OK","Error") -> OK | R38: =IF(ABS(R29-R33-R36)<0.0001,"OK","Error") -> OK
B40: Other Non Operating Expense % of Revenue | C40: = | D40: Other Non Operating Expenses | E40: = | F40: =F26 -> 512528 | G40: =G26 -> 540877 | H40: =H26 -> 504569 | I40: =I26 -> 522219 | J40: =J26 -> 531151 | K40: =K26 -> 577389 | L40: = | M40: =IF(F41=0,,F40/F41) -> 0.14813847 | N40: =IF(G41=0,,G40/G41) -> 0.12664257 | O40: =IF(H41=0,,H40/H41) -> 0.099027252 | P40: =IF(I41=0,,I40/I41) -> 0.08747173 | Q40: =IF(J41=0,,J40/J41) -> 0.079553304 | R40: =IF(K41=0,,K40/K41) -> 0.080801532
D41: =+D37 -> Revenue | F41: =F37 -> 3459790 | G41: =G37 -> 4270894 | H41: =H37 -> 5095254 | I41: =I37 -> 5970146 | J41: =J37 -> 6676668 | K41: =K37 -> 7145768
B44: EBT Margin | C44: = | D44: Earning Before Tax | E44: = | F44: ='Financial Statements'!F28 -> 667035 | G44: ='Financial Statements'!G28 -> 1042231 | H44: ='Financial Statements'!H28 -> 1177766 | I44: ='Financial Statements'!I28 -> 1602354 | J44: ='Financial Statements'!J28 -> 1888956 | K44: ='Financial Statements'!K28 -> 2063634 | L44: = | M44: =IF(F45=0,,F44/F45) -> 0.19279638 | N44: =IF(G45=0,,G44/G45) -> 0.24403111 | O44: =IF(H45=0,,H44/H45) -> 0.23114961 | P44: =IF(I45=0,,I44/I45) -> 0.26839444 | Q44: =IF(J45=0,,J44/J45) -> 0.28291896 | R44: =IF(K45=0,,K44/K45) -> 0.28879107
D45: =+D52 -> Revenue | F45: =F41 -> 3459790 | G45: =G41 -> 4270894 | H45: =H41 -> 5095254 | I45: =I41 -> 5970146 | J45: =J41 -> 6676668 | K45: =K41 -> 7145768
B46: Check | M46: =IF(ABS(M36-M40-M44)<0.0001,"OK","Error") -> Error | N46: =IF(ABS(N36-N40-N44)<0.0001,"OK","Error") -> Error | O46: =IF(ABS(O36-O40-O44)<0.0001,"OK","Error") -> Error | P46: =IF(ABS(P36-P40-P44)<0.0001,"OK","Error") -> Error | Q46: =IF(ABS(Q36-Q40-Q44)<0.0001,"OK","Error") -> Error | R46: =IF(ABS(R36-R40-R44)<0.0001,"OK","Error") -> Error
B48: Tax % of Revenue | C48: = | D48: Tax | E48: = | F48: =-'Financial Statements'!F31 -> 58155 | G48: =-'Financial Statements'!G31 -> 209095 | H48: =-'Financial Statements'!H31 -> 238472 | I48: =-'Financial Statements'!I31 -> 344897 | J48: =-'Financial Statements'!J31 -> 363043 | K48: =-'Financial Statements'!K31 -> 464119 | L48: = | M48: =IF(F49=0,,F48/F49) -> 0.016808824 | N48: =IF(G49=0,,G48/G49) -> 0.048958134 | O48: =IF(H49=0,,H48/H49) -> 0.04680277 | P48: =IF(I49=0,,I48/I49) -> 0.057770279 | Q48: =IF(J49=0,,J48/J49) -> 0.054374877 | R48: =IF(K49=0,,K48/K49) -> 0.064950191
D49: =+D21 -> Revenue | F49: =F45 -> 3459790 | G49: =G45 -> 4270894 | H49: =H45 -> 5095254 | I49: =I45 -> 5970146 | J49: =J45 -> 6676668 | K49: =K45 -> 7145768
B51: Net Profit Margin | C51: = | D51: =D11 -> Net Income | E51: = | F51: =F11 -> 608880 | G51: =G11 -> 833136 | H51: =H11 -> 939294 | I51: =I11 -> 1257457 | J51: =J11 -> 1525913 | K51: =K11 -> 1599515 | L51: = | M51: =IF(F52=0,,F51/F52) -> 0.17598756 | N51: =IF(G52=0,,G51/G52) -> 0.19507298 | O51: =IF(H52=0,,H51/H52) -> 0.18434685 | P51: =IF(I52=0,,I51/I52) -> 0.21062416 | Q51: =IF(J52=0,,J51/J52) -> 0.22854409 | R51: =IF(K52=0,,K51/K52) -> 0.22384088
D52: Revenue | F52: =F49 -> 3459790 | G52: =G49 -> 4270894 | H52: =H49 -> 5095254 | I52: =I49 -> 5970146 | J52: =J49 -> 6676668 | K52: =K49 -> 7145768
B53: Check | M53: =IF(ABS(M44-M48-M51)<0.0001,"OK","Error") -> OK | N53: =IF(ABS(N44-N48-N51)<0.0001,"OK","Error") -> OK | O53: =IF(ABS(O44-O48-O51)<0.0001,"OK","Error") -> OK | P53: =IF(ABS(P44-P48-P51)<0.0001,"OK","Error") -> OK | Q53: =IF(ABS(Q44-Q48-Q51)<0.0001,"OK","Error") -> OK | R53: =IF(ABS(R44-R48-R51)<0.0001,"OK","Error") -> OK
B55: Effective Tax Rate | C55: = | D55: Tax | E55: = | F55: =F48 -> 58155 | G55: =G48 -> 209095 | H55: =H48 -> 238472 | I55: =I48 -> 344897 | J55: =J48 -> 363043 | K55: =K48 -> 464119 | L55: = | M55: =IF(F56=0,,F55/F56) -> 0.087184331 | N55: =IF(G56=0,,G55/G56) -> 0.20062251 | O55: =IF(H56=0,,H55/H56) -> 0.20247825 | P55: =IF(I56=0,,I55/I56) -> 0.21524395 | Q55: =IF(J56=0,,J55/J56) -> 0.19219241 | R55: =IF(K56=0,,K55/K56) -> 0.22490374
D56: =+D44 -> Earning Before Tax | F56: =F44 -> 667035 | G56: =G44 -> 1042231 | H56: =H44 -> 1177766 | I56: =I44 -> 1602354 | J56: =J44 -> 1888956 | K56: =K44 -> 2063634
B58: Tax Burden | C58: = | D58: Net Income | E58: = | F58: =F51 -> 608880 | G58: =G51 -> 833136 | H58: =H51 -> 939294 | I58: =I51 -> 1257457 | J58: =J51 -> 1525913 | K58: =K51 -> 1599515 | L58: = | M58: =IF(F59=0,,F58/F59) -> 0.91281567 | N58: =IF(G59=0,,G58/G59) -> 0.79937749 | O58: =IF(H59=0,,H58/H59) -> 0.79752175 | P58: =IF(I59=0,,I58/I59) -> 0.78475605 | Q58: =IF(J59=0,,J58/J59) -> 0.80780759 | R58: =IF(K59=0,,K58/K59) -> 0.77509626
D59: =+D56 -> Earning Before Tax | F59: =F56 -> 667035 | G59: =G56 -> 1042231 | H59: =H56 -> 1177766 | I59: =I56 -> 1602354 | J59: =J56 -> 1888956 | K59: =K56 -> 2063634
B61: Effective Interest Rate | C61: = | D61: Interest Expense | E61: = | F61: =-'Financial Statements'!F26 -> 49092 | G61: =-'Financial Statements'!G26 -> 76256 | H61: =-'Financial Statements'!H26 -> 133474 | I61: =-'Financial Statements'!I26 -> 147334 | J61: =-'Financial Statements'!J26 -> 145895 | K61: =-'Financial Statements'!K26 -> 214226 | L61: = | M61: =IF(F62=0,,F61/F62) -> 0.018017099 | N61: =IF(G62=0,,G61/G62) -> 0.028994556 | O61: =IF(H62=0,,H61/H62) -> 0.047469591 | P61: =IF(I62=0,,I61/I62) -> 0.059476357 | Q61: =IF(J62=0,,J61/J62) -> 0.043526216 | R61: =IF(K62=0,,K61/K62) -> 0.074275194
...

Sheet 3 Step DuPont Pyramid 
AJ1: by/ m.salama
N4: ='Ratio Calculations'!B8 -> Return on Equity
N5: 2020 | O5: 2021 | P5: 2022 | Q5: 2023 | R5: 2024 | S5: 2025
N6: ='Ratio Calculations'!M8 -> 0.34030776 | O6: ='Ratio Calculations'!N8 -> 0.37674323 | P6: ='Ratio Calculations'!O8 -> 0.36092169 | Q6: ='Ratio Calculations'!P8 -> 0.40951214 | R6: ='Ratio Calculations'!Q8 -> 0.43065495 | S6: ='Ratio Calculations'!R8 -> 0.40858759 | AC6: Working Capital Analysis
G8: ='Ratio Calculations'!B51 -> Net Profit Margin | N8: ='Ratio Calculations'!B111 -> Total Asset to Equity | U8: ='Ratio Calculations'!B73 -> Asset Turnover | AD8: ='Ratio Calculations'!B82 -> Cash Days
G9: 2020 | H9: 2021 | I9: 2022 | J9: 2023 | K9: 2024 | L9: 2025 | N9: 2020 | O9: 2021 | P9: 2022 | Q9: 2023 | R9: 2024 | S9: 2025 | U9: 2020 | V9: 2021 | W9: 2022 | X9: 2023 | Y9: 2024 | Z9: 2025 | AD9: 2020 | AE9: 2021 | AF9: 2022 | AG9: 2023 | AH9: 2024 | AI9: 2025
G10: ='Ratio Calculations'!M51 -> 0.17598756 | H10: ='Ratio Calculations'!N51 -> 0.19507298 | I10: ='Ratio Calculations'!O51 -> 0.18434685 | J10: ='Ratio Calculations'!P51 -> 0.21062416 | K10: ='Ratio Calculations'!Q51 -> 0.22854409 | L10: ='Ratio Calculations'!R51 -> 0.22384088 | N10: ='Ratio Calculations'!M111 -> 3.4999067 | O10: ='Ratio Calculations'!N111 -> 3.1036698 | P10: ='Ratio Calculations'!O111 -> 2.9840007 | Q10: ='Ratio Calculations'!P111 -> 2.622046 | R10: ='Ratio Calculations'!Q111 -> 2.6803579 | S10: ='Ratio Calculations'!R111 -> 2.4595113 | U10: ='Ratio Calculations'!M73 -> 0.55250144 | V10: ='Ratio Calculations'!N73 -> 0.62226137 | W10: ='Ratio Calculations'!O73 -> 0.65611256 | X10: ='Ratio Calculations'!P73 -> 0.74151219 | Y10: ='Ratio Calculations'!Q73 -> 0.70301836 | Z10: ='Ratio Calculations'!R73 -> 0.74215899 | AD10: ='Ratio Calculations'!M82 -> 143.73074 | AE10: ='Ratio Calculations'!N82 -> 114.87368 | AF10: ='Ratio Calculations'!O82 -> 99.494326 | AG10: ='Ratio Calculations'!P82 -> 68.595151 | AH10: ='Ratio Calculations'!Q82 -> 95.243332 | AI10: ='Ratio Calculations'!R82 -> 74.969481
C12: ='Ratio Calculations'!B44 -> EBT Margin | K12: ='Ratio Calculations'!B48 -> Tax % of Revenue | U12: ='Ratio Calculations'!B79 -> Cash Turnover | AD12: ='Ratio Calculations'!B88 -> A/R Days
C13: 2020 | D13: 2021 | E13: 2022 | F13: 2023 | G13: 2024 | H13: 2025 | K13: 2020 | L13: 2021 | M13: 2022 | N13: 2023 | O13: 2024 | P13: 2025 | U13: 2020 | V13: 2021 | W13: 2022 | X13: 2023 | Y13: 2024 | Z13: 2025 | AD13: 2020 | AE13: 2021 | AF13: 2022 | AG13: 2023 | AH13: 2024 | AI13: 2025
C14: ='Ratio Calculations'!M44 -> 0.19279638 | D14: ='Ratio Calculations'!N44 -> 0.24403111 | E14: ='Ratio Calculations'!O44 -> 0.23114961 | F14: ='Ratio Calculations'!P44 -> 0.26839444 | G14: ='Ratio Calculations'!Q44 -> 0.28291896 | H14: ='Ratio Calculations'!R44 -> 0.28879107 | K14: ='Ratio Calculations'!M48 -> 0.016808824 | L14: ='Ratio Calculations'!N48 -> 0.048958134 | M14: ='Ratio Calculations'!O48 -> 0.04680277 | N14: ='Ratio Calculations'!P48 -> 0.057770279 | O14: ='Ratio Calculations'!Q48 -> 0.054374877 | P14: ='Ratio Calculations'!R48 -> 0.064950191 | U14: ='Ratio Calculations'!M79 -> 2.5394706 | V14: ='Ratio Calculations'!N79 -> 3.1774033 | W14: ='Ratio Calculations'!O79 -> 3.6685509 | X14: ='Ratio Calculations'!P79 -> 5.3210758 | Y14: ='Ratio Calculations'!Q79 -> 3.8322893 | Z14: ='Ratio Calculations'!R79 -> 4.8686478 | AD14: ='Ratio Calculations'!M88 -> 19.439012 | AE14: ='Ratio Calculations'!N88 -> 15.810507 | AF14: ='Ratio Calculations'!O88 -> 16.649044 | AG14: ='Ratio Calculations'!P88 -> 15.980128 | AH14: ='Ratio Calculations'!Q88 -> 19.088749 | AI14: ='Ratio Calculations'!R88 -> 18.405822
C16: ='Ratio Calculations'!B36 -> EBIT Margin | K16: ='Ratio Calculations'!B40 -> Other Non Operating Expense % of Revenue | U16: ='Ratio Calculations'!B85 -> A/R Turnover | AD16: ='Ratio Calculations'!B94 -> Inventory Days
C17: 2020 | D17: 2021 | E17: 2022 | F17: 2023 | G17: 2024 | H17: 2025 | K17: 2020 | L17: 2021 | M17: 2022 | N17: 2023 | O17: 2024 | P17: 2025 | U17: 2020 | V17: 2021 | W17: 2022 | X17: 2023 | Y17: 2024 | Z17: 2025 | AD17: 2020 | AE17: 2021 | AF17: 2022 | AG17: 2023 | AH17: 2024 | AI17: 2025
C18: ='Ratio Calculations'!M36 -> 0.20698568 | D18: ='Ratio Calculations'!N36 -> 0.251818 | E18: ='Ratio Calculations'!O36 -> 0.2408873 | F18: ='Ratio Calculations'!P36 -> 0.27090946 | G18: ='Ratio Calculations'!Q36 -> 0.28273849 | H18: ='Ratio Calculations'!R36 -> 0.29523978 | K18: ='Ratio Calculations'!M40 -> 0.14813847 | L18: ='Ratio Calculations'!N40 -> 0.12664257 | M18: ='Ratio Calculations'!O40 -> 0.099027252 | N18: ='Ratio Calculations'!P40 -> 0.08747173 | O18: ='Ratio Calculations'!Q40 -> 0.079553304 | P18: ='Ratio Calculations'!R40 -> 0.080801532 | U18: ='Ratio Calculations'!M85 -> 18.776674 | V18: ='Ratio Calculations'!N85 -> 23.085914 | W18: ='Ratio Calculations'!O85 -> 21.92318 | X18: ='Ratio Calculations'!P85 -> 22.840868 | Y18: ='Ratio Calculations'!Q85 -> 19.121211 | Z18: ='Ratio Calculations'!R85 -> 19.830682 | AD18: ='Ratio Calculations'!M94 -> 114.49769 | AE18: ='Ratio Calculations'!N94 -> 106.62425 | AF18: ='Ratio Calculations'!O94 -> 103.0728 | AG18: ='Ratio Calculations'!P94 -> 127.95619 | AH18: ='Ratio Calculations'!Q94 -> 131.09278 | AI18: ='Ratio Calculations'!R94 -> 128.89804
C20: ='Ratio Calculations'!B29 -> EBITDA Margin | K20: ='Ratio Calculations'!B33 -> Depreciation % of Revenue | U20: ='Ratio Calculations'!B91 -> Inventory Turnover | AD20: ='Ratio Calculations'!B100 -> A/P Days
C21: 2020 | D21: 2021 | E21: 2022 | F21: 2023 | G21: 2024 | H21: 2025 | K21: 2020 | L21: 2021 | M21: 2022 | N21: 2023 | O21: 2024 | P21: 2025 | U21: 2020 | V21: 2021 | W21: 2022 | X21: 2023 | Y21: 2024 | Z21: 2025 | AD21: 2020 | AE21: 2021 | AF21: 2022 | AG21: 2023 | AH21: 2024 | AI21: 2025
C22: ='Ratio Calculations'!M29 -> 0.33029866 | D22: ='Ratio Calculations'!N29 -> 0.35858464 | E22: ='Ratio Calculations'!O29 -> 0.34809001 | F22: ='Ratio Calculations'!P29 -> 0.3818456 | G22: ='Ratio Calculations'!Q29 -> 0.38260522 | H22: ='Ratio Calculations'!R29 -> 0.38787321 | K22: ='Ratio Calculations'!M33 -> 0.12331298 | L22: ='Ratio Calculations'!N33 -> 0.10676664 | M22: ='Ratio Calculations'!O33 -> 0.1072027 | N22: ='Ratio Calculations'!P33 -> 0.11093615 | O22: ='Ratio Calculations'!Q33 -> 0.09986673 | P22: ='Ratio Calculations'!R33 -> 0.09263343 | U22: ='Ratio Calculations'!M91 -> 3.1878372 | V22: ='Ratio Calculations'!N91 -> 3.4232364 | W22: ='Ratio Calculations'!O91 -> 3.5411865 | X22: ='Ratio Calculations'!P91 -> 2.8525388 | Y22: ='Ratio Calculations'!Q91 -> 2.7842875 | Z22: ='Ratio Calculations'!R91 -> 2.8316956 | AD22: ='Ratio Calculations'!M100 -> 177.4343 | AE22: ='Ratio Calculations'!N100 -> 157.3662 | AF22: ='Ratio Calculations'!O100 -> 137.95269 | AG22: ='Ratio Calculations'!P100 -> 125.53416 | AH22: ='Ratio Calculations'!Q100 -> 113.9216 | AI22: ='Ratio Calculations'!R100 -> 97.347929
C24: ='Ratio Calculations'!B20 -> Gross Margin | K24: ='Ratio Calculations'!B26 -> Other Operating Expenses % of Revenue | U24: ='Ratio Calculations'!B76 -> PPE Turnover | AD24: ='Ratio Calculations'!B103 -> Cash Conversion Cycle / WC Funding Gap
C25: 2020 | D25: 2021 | E25: 2022 | F25: 2023 | G25: 2024 | H25: 2025 | K25: 2020 | L25: 2021 | M25: 2022 | N25: 2023 | O25: 2024 | P25: 2025 | U25: 2020 | V25: 2021 | W25: 2022 | X25: 2023 | Y25: 2024 | Z25: 2025 | AD25: 2020 | AE25: 2021 | AF25: 2022 | AG25: 2023 | AH25: 2024 | AI25: 2025
C26: ='Ratio Calculations'!M20 -> 0.57558927 | D26: ='Ratio Calculations'!N20 -> 0.5667146 | E26: ='Ratio Calculations'!O20 -> 0.53111189 | F26: ='Ratio Calculations'!P20 -> 0.54679953 | G26: ='Ratio Calculations'!Q20 -> 0.54620403 | H26: ='Ratio Calculations'!R20 -> 0.5585867 | K26: ='Ratio Calculations'!M26 -> 0.14813847 | L26: ='Ratio Calculations'!N26 -> 0.12664257 | M26: ='Ratio Calculations'!O26 -> 0.099027252 | N26: ='Ratio Calculations'!P26 -> 0.08747173 | O26: ='Ratio Calculations'!Q26 -> 0.079553304 | P26: ='Ratio Calculations'!R26 -> 0.080801532 | U26: ='Ratio Calculations'!M76 -> 2.8205653 | V26: ='Ratio Calculations'!N76 -> 3.1562256 | W26: ='Ratio Calculations'!O76 -> 3.4951068 | X26: ='Ratio Calculations'!P76 -> 3.7900876 | Y26: ='Ratio Calculations'!Q76 -> 3.6508784 | Z26: ='Ratio Calculations'!R76 -> 3.4723744 | AD26: ='Ratio Calculations'!M103 -> -43.497594 | AE26: ='Ratio Calculations'!N103 -> -34.931451 | AF26: ='Ratio Calculations'!O103 -> -18.230848 | AG26: ='Ratio Calculations'!P103 -> 18.402154 | AH26: ='Ratio Calculations'!Q103 -> 36.259926 | AI26: ='Ratio Calculations'!R103 -> 49.955931
K28: ='Ratio Calculations'!B23 -> SG&A % of Revenue
K29: 2020 | L29: 2021 | M29: 2022 | N29: 2023 | O29: 2024 | P29: 2025
K30: ='Ratio Calculations'!M23 -> 0.097152139 | L30: ='Ratio Calculations'!N23 -> 0.081487389 | M30: ='Ratio Calculations'!O23 -> 0.083994635 | N30: ='Ratio Calculations'!P23 -> 0.077482192 | O30: ='Ratio Calculations'!Q23 -> 0.084045515 | P30: ='Ratio Calculations'!R23 -> 0.089911959 | AC30: Leverage Analysis
C31: Growth Analysis | AD31: ='Ratio Calculations'!B117 -> Debt to Equity
D32: ='Ratio Calculations'!B147 -> Revenue Growth | AD32: 2020 | AE32: 2021 | AF32: 2022 | AG32: 2023 | AH32: 2024 | AI32: 2025
D33: 2021 | E33: 2022 | F33: 2023 | G33: 2024 | H33: 2025 | AD33: ='Ratio Calculations'!M117 -> 1.5228811 | AE33: ='Ratio Calculations'!N117 -> 1.1892882 | AF33: ='Ratio Calculations'!O117 -> 1.08042 | AG33: ='Ratio Calculations'!P117 -> 0.80673753 | AH33: ='Ratio Calculations'!Q117 -> 0.94599572 | AI33: ='Ratio Calculations'!R117 -> 0.73675864
D34: ='Ratio Calculations'!N147 -> 0.23443735 | E34: ='Ratio Calculations'!O147 -> 0.19301814 | F34: ='Ratio Calculations'!P147 -> 0.17170724 | G34: ='Ratio Calculations'!Q147 -> 0.1183425 | H34: ='Ratio Calculations'!R147 -> 0.070259597
AD35: ='Ratio Calculations'!B120 -> Debt to EBITDA
D36: ='Ratio Calculations'!B150 -> EBITDA Growth | AD36: 2020 | AE36: 2021 | AF36: 2022 | AG36: 2023 | AH36: 2024 | AI36: 2025
D37: 2021 | E37: 2022 | F37: 2023 | G37: 2024 | H37: 2025 | AD37: ='Ratio Calculations'!M120 -> 2.3843462 | AE37: ='Ratio Calculations'!N120 -> 1.7173036 | AF37: ='Ratio Calculations'!O120 -> 1.585345 | AG37: ='Ratio Calculations'!P120 -> 1.0866405 | AH37: ='Ratio Calculations'!Q120 -> 1.3121359 | AI37: ='Ratio Calculations'!R120 -> 1.040614
D38: ='Ratio Calculations'!N150 -> 0.3401516 | E38: ='Ratio Calculations'!O150 -> 0.15810228 | F38: ='Ratio Calculations'!P150 -> 0.28533209 | G38: ='Ratio Calculations'!Q150 -> 0.12056724 | H38: ='Ratio Calculations'!R150 -> 0.084995741
AD39: ='Ratio Calculations'!B132 -> Current
D40: ='Ratio Calculations'!B156 -> Net Income Growth | AD40: 2020 | AE40: 2021 | AF40: 2022 | AG40: 2023 | AH40: 2024 | AI40: 2025
D41: 2021 | E41: 2022 | F41: 2023 | G41: 2024 | H41: 2025 | AD41: ='Ratio Calculations'!M132 -> 1.3323978 | AE41: ='Ratio Calculations'!N132 -> 1.5358353 | AF41: ='Ratio Calculations'!O132 -> 1.3568797 | AG41: ='Ratio Calculations'!P132 -> 1.4249938 | AH41: ='Ratio Calculations'!Q132 -> 1.4400503 | AI41: ='Ratio Calculations'!R132 -> 1.504074
D42: ='Ratio Calculations'!N156 -> 0.36830903 | E42: ='Ratio Calculations'!O156 -> 0.12741977 | F42: ='Ratio Calculations'!P156 -> 0.33872568 | G42: ='Ratio Calculations'!Q156 -> 0.2134912 | H42: ='Ratio Calculations'!R156 -> 0.048234729
AD43: ='Ratio Calculations'!B135 -> Quick
D44: ='Ratio Calculations'!B159 -> Total Asset Growth | AD44: 2020 | AE44: 2021 | AF44: 2022 | AG44: 2023 | AH44: 2024 | AI44: 2025
D45: 2021 | E45: 2022 | F45: 2023 | G45: 2024 | H45: 2025 | AD45: ='Ratio Calculations'!M135 -> 1.1328697 | AE45: ='Ratio Calculations'!N135 -> 1.289015 | AF45: ='Ratio Calculations'!O135 -> 1.1252713 | AG45: ='Ratio Calculations'!P135 -> 1.085901 | AH45: ='Ratio Calculations'!Q135 -> 1.1278821 | AI45: ='Ratio Calculations'!R135 -> 1.1567969
D46: ='Ratio Calculations'!N159 -> 0.096048145 | E46: ='Ratio Calculations'!O159 -> 0.13146607 | F46: ='Ratio Calculations'!P159 -> 0.036762234 | G46: ='Ratio Calculations'!Q159 -> 0.17957744 | H46: ='Ratio Calculations'!R159 -> 0.013815308
AD47: ='Ratio Calculations'!B138 -> Interest Coverage
D48: ='Ratio Calculations'!B162 -> Degree of Operating Leverage | AD48: 2020 | AE48: 2021 | AF48: 2022 | AG48: 2023 | AH48: 2024 | AI48: 2025
...

Sheet 5 Step DuPont 
AT1: by/ m.salama
X4: ='Ratio Calculations'!B8 -> Return on Equity
X5: 2020 | Y5: 2021 | Z5: 2022 | AA5: 2023 | AB5: 2024 | AC5: 2025
X6: ='Ratio Calculations'!M8 -> 0.34030776 | Y6: ='Ratio Calculations'!N8 -> 0.37674323 | Z6: ='Ratio Calculations'!O8 -> 0.36092169 | AA6: ='Ratio Calculations'!P8 -> 0.40951214 | AB6: ='Ratio Calculations'!Q8 -> 0.43065495 | AC6: ='Ratio Calculations'!R8 -> 0.40858759 | AM6: Working Capital Analysis
C8: ='Ratio Calculations'!B58 -> Tax Burden | J8: ='Ratio Calculations'!B64 -> Interest Burden | Q8: ='Ratio Calculations'!B36 -> EBIT Margin | X8: ='Ratio Calculations'!B111 -> Total Asset to Equity | AE8: ='Ratio Calculations'!B73 -> Asset Turnover | AN8: ='Ratio Calculations'!B82 -> Cash Days
C9: 2020 | D9: 2021 | E9: 2022 | F9: 2023 | G9: 2024 | H9: 2025 | J9: 2020 | K9: 2021 | L9: 2022 | M9: 2023 | N9: 2024 | O9: 2025 | Q9: 2020 | R9: 2021 | S9: 2022 | T9: 2023 | U9: 2024 | V9: 2025 | X9: 2020 | Y9: 2021 | Z9: 2022 | AA9: 2023 | AB9: 2024 | AC9: 2025 | AE9: 2020 | AF9: 2021 | AG9: 2022 | AH9: 2023 | AI9: 2024 | AJ9: 2025 | AN9: 2020 | AO9: 2021 | AP9: 2022 | AQ9: 2023 | AR9: 2024 | AS9: 2025
C10: ='Ratio Calculations'!M58 -> 0.91281567 | D10: ='Ratio Calculations'!N58 -> 0.79937749 | E10: ='Ratio Calculations'!O58 -> 0.79752175 | F10: ='Ratio Calculations'!P58 -> 0.78475605 | G10: ='Ratio Calculations'!Q58 -> 0.80780759 | H10: ='Ratio Calculations'!R58 -> 0.77509626 | J10: ='Ratio Calculations'!M64 -> 0.93144791 | K10: ='Ratio Calculations'!N64 -> 0.96907729 | L10: ='Ratio Calculations'!O64 -> 0.95957575 | M10: ='Ratio Calculations'!P64 -> 0.9907164 | N10: ='Ratio Calculations'!Q64 -> 1.0006383 | O10: ='Ratio Calculations'!R64 -> 0.97815771 | Q10: ='Ratio Calculations'!M36 -> 0.20698568 | R10: ='Ratio Calculations'!N36 -> 0.251818 | S10: ='Ratio Calculations'!O36 -> 0.2408873 | T10: ='Ratio Calculations'!P36 -> 0.27090946 | U10: ='Ratio Calculations'!Q36 -> 0.28273849 | V10: ='Ratio Calculations'!R36 -> 0.29523978 | X10: ='Ratio Calculations'!M111 -> 3.4999067 | Y10: ='Ratio Calculations'!N111 -> 3.1036698 | Z10: ='Ratio Calculations'!O111 -> 2.9840007 | AA10: ='Ratio Calculations'!P111 -> 2.622046 | AB10: ='Ratio Calculations'!Q111 -> 2.6803579 | AC10: ='Ratio Calculations'!R111 -> 2.4595113 | AE10: ='Ratio Calculations'!M73 -> 0.55250144 | AF10: ='Ratio Calculations'!N73 -> 0.62226137 | AG10: ='Ratio Calculations'!O73 -> 0.65611256 | AH10: ='Ratio Calculations'!P73 -> 0.74151219 | AI10: ='Ratio Calculations'!Q73 -> 0.70301836 | AJ10: ='Ratio Calculations'!R73 -> 0.74215899 | AN10: ='Ratio Calculations'!M82 -> 143.73074 | AO10: ='Ratio Calculations'!N82 -> 114.87368 | AP10: ='Ratio Calculations'!O82 -> 99.494326 | AQ10: ='Ratio Calculations'!P82 -> 68.595151 | AR10: ='Ratio Calculations'!Q82 -> 95.243332 | AS10: ='Ratio Calculations'!R82 -> 74.969481
AE12: ='Ratio Calculations'!B79 -> Cash Turnover | AN12: ='Ratio Calculations'!B88 -> A/R Days
M13: ='3 Step DuPont Pyramid '!C20 -> EBITDA Margin | U13: ='3 Step DuPont Pyramid '!K20 -> Depreciation % of Revenue | AE13: 2020 | AF13: 2021 | AG13: 2022 | AH13: 2023 | AI13: 2024 | AJ13: 2025 | AN13: 2020 | AO13: 2021 | AP13: 2022 | AQ13: 2023 | AR13: 2024 | AS13: 2025
M14: 2020 | N14: 2021 | O14: 2022 | P14: 2023 | Q14: 2024 | R14: 2025 | U14: 2020 | V14: 2021 | W14: 2022 | X14: 2023 | Y14: 2024 | Z14: 2025 | AE14: ='Ratio Calculations'!M79 -> 2.5394706 | AF14: ='Ratio Calculations'!N79 -> 3.1774033 | AG14: ='Ratio Calculations'!O79 -> 3.6685509 | AH14: ='Ratio Calculations'!P79 -> 5.3210758 | AI14: ='Ratio Calculations'!Q79 -> 3.8322893 | AJ14: ='Ratio Calculations'!R79 -> 4.8686478 | AN14: ='Ratio Calculations'!M88 -> 19.439012 | AO14: ='Ratio Calculations'!N88 -> 15.810507 | AP14: ='Ratio Calculations'!O88 -> 16.649044 | AQ14: ='Ratio Calculations'!P88 -> 15.980128 | AR14: ='Ratio Calculations'!Q88 -> 19.088749 | AS14: ='Ratio Calculations'!R88 -> 18.405822
M15: ='3 Step DuPont Pyramid '!C22 -> 0.33029866 | N15: ='3 Step DuPont Pyramid '!D22 -> 0.35858464 | O15: ='3 Step DuPont Pyramid '!E22 -> 0.34809001 | P15: ='3 Step DuPont Pyramid '!F22 -> 0.3818456 | Q15: ='3 Step DuPont Pyramid '!G22 -> 0.38260522 | R15: ='3 Step DuPont Pyramid '!H22 -> 0.38787321 | U15: ='3 Step DuPont Pyramid '!K22 -> 0.12331298 | V15: ='3 Step DuPont Pyramid '!L22 -> 0.10676664 | W15: ='3 Step DuPont Pyramid '!M22 -> 0.1072027 | X15: ='3 Step DuPont Pyramid '!N22 -> 0.11093615 | Y15: ='3 Step DuPont Pyramid '!O22 -> 0.09986673 | Z15: ='3 Step DuPont Pyramid '!P22 -> 0.09263343
AE16: ='Ratio Calculations'!B85 -> A/R Turnover | AN16: ='Ratio Calculations'!B94 -> Inventory Days
M17: ='3 Step DuPont Pyramid '!C24 -> Gross Margin | U17: ='3 Step DuPont Pyramid '!K16 -> Other Non Operating Expense % of Revenue | AE17: 2020 | AF17: 2021 | AG17: 2022 | AH17: 2023 | AI17: 2024 | AJ17: 2025 | AN17: 2020 | AO17: 2021 | AP17: 2022 | AQ17: 2023 | AR17: 2024 | AS17: 2025
M18: 2020 | N18: 2021 | O18: 2022 | P18: 2023 | Q18: 2024 | R18: 2025 | U18: 2020 | V18: 2021 | W18: 2022 | X18: 2023 | Y18: 2024 | Z18: 2025 | AE18: ='Ratio Calculations'!M85 -> 18.776674 | AF18: ='Ratio Calculations'!N85 -> 23.085914 | AG18: ='Ratio Calculations'!O85 -> 21.92318 | AH18: ='Ratio Calculations'!P85 -> 22.840868 | AI18: ='Ratio Calculations'!Q85 -> 19.121211 | AJ18: ='Ratio Calculations'!R85 -> 19.830682 | AN18: ='Ratio Calculations'!M94 -> 114.49769 | AO18: ='Ratio Calculations'!N94 -> 106.62425 | AP18: ='Ratio Calculations'!O94 -> 103.0728 | AQ18: ='Ratio Calculations'!P94 -> 127.95619 | AR18: ='Ratio Calculations'!Q94 -> 131.09278 | AS18: ='Ratio Calculations'!R94 -> 128.89804
M19: ='3 Step DuPont Pyramid '!C26 -> 0.57558927 | N19: ='3 Step DuPont Pyramid '!D26 -> 0.5667146 | O19: ='3 Step DuPont Pyramid '!E26 -> 0.53111189 | P19: ='3 Step DuPont Pyramid '!F26 -> 0.54679953 | Q19: ='3 Step DuPont Pyramid '!G26 -> 0.54620403 | R19: ='3 Step DuPont Pyramid '!H26 -> 0.5585867 | U19: ='3 Step DuPont Pyramid '!K18 -> 0.14813847 | V19: ='3 Step DuPont Pyramid '!L18 -> 0.12664257 | W19: ='3 Step DuPont Pyramid '!M18 -> 0.099027252 | X19: ='3 Step DuPont Pyramid '!N18 -> 0.08747173 | Y19: ='3 Step DuPont Pyramid '!O18 -> 0.079553304 | Z19: ='3 Step DuPont Pyramid '!P18 -> 0.080801532
AE20: ='Ratio Calculations'!B91 -> Inventory Turnover | AN20: ='Ratio Calculations'!B100 -> A/P Days
U21: ='3 Step DuPont Pyramid '!K28 -> SG&A % of Revenue | AE21: 2020 | AF21: 2021 | AG21: 2022 | AH21: 2023 | AI21: 2024 | AJ21: 2025 | AN21: 2020 | AO21: 2021 | AP21: 2022 | AQ21: 2023 | AR21: 2024 | AS21: 2025
U22: 2020 | V22: 2021 | W22: 2022 | X22: 2023 | Y22: 2024 | Z22: 2025 | AE22: ='Ratio Calculations'!M91 -> 3.1878372 | AF22: ='Ratio Calculations'!N91 -> 3.4232364 | AG22: ='Ratio Calculations'!O91 -> 3.5411865 | AH22: ='Ratio Calculations'!P91 -> 2.8525388 | AI22: ='Ratio Calculations'!Q91 -> 2.7842875 | AJ22: ='Ratio Calculations'!R91 -> 2.8316956 | AN22: ='Ratio Calculations'!M100 -> 177.4343 | AO22: ='Ratio Calculations'!N100 -> 157.3662 | AP22: ='Ratio Calculations'!O100 -> 137.95269 | AQ22: ='Ratio Calculations'!P100 -> 125.53416 | AR22: ='Ratio Calculations'!Q100 -> 113.9216 | AS22: ='Ratio Calculations'!R100 -> 97.347929
U23: ='3 Step DuPont Pyramid '!K30 -> 0.097152139 | V23: ='3 Step DuPont Pyramid '!L30 -> 0.081487389 | W23: ='3 Step DuPont Pyramid '!M30 -> 0.083994635 | X23: ='3 Step DuPont Pyramid '!N30 -> 0.077482192 | Y23: ='3 Step DuPont Pyramid '!O30 -> 0.084045515 | Z23: ='3 Step DuPont Pyramid '!P30 -> 0.089911959
AE24: ='Ratio Calculations'!B76 -> PPE Turnover | AN24: ='Ratio Calculations'!B103 -> Cash Conversion Cycle / WC Funding Gap
AE25: 2020 | AF25: 2021 | AG25: 2022 | AH25: 2023 | AI25: 2024 | AJ25: 2025 | AN25: 2020 | AO25: 2021 | AP25: 2022 | AQ25: 2023 | AR25: 2024 | AS25: 2025
AE26: ='Ratio Calculations'!M76 -> 2.8205653 | AF26: ='Ratio Calculations'!N76 -> 3.1562256 | AG26: ='Ratio Calculations'!O76 -> 3.4951068 | AH26: ='Ratio Calculations'!P76 -> 3.7900876 | AI26: ='Ratio Calculations'!Q76 -> 3.6508784 | AJ26: ='Ratio Calculations'!R76 -> 3.4723744 | AN26: ='Ratio Calculations'!M103 -> -43.497594 | AO26: ='Ratio Calculations'!N103 -> -34.931451 | AP26: ='Ratio Calculations'!O103 -> -18.230848 | AQ26: ='Ratio Calculations'!P103 -> 18.402154 | AR26: ='Ratio Calculations'!Q103 -> 36.259926 | AS26: ='Ratio Calculations'!R103 -> 49.955931
AM30: Leverage Analysis
M31: Growth Analysis | AN31: ='Ratio Calculations'!B117 -> Debt to Equity
N32: ='Ratio Calculations'!B147 -> Revenue Growth | AN32: 2020 | AO32: 2021 | AP32: 2022 | AQ32: 2023 | AR32: 2024 | AS32: 2025
N33: 2021 | O33: 2022 | P33: 2023 | Q33: 2024 | R33: 2025 | AN33: ='Ratio Calculations'!M117 -> 1.5228811 | AO33: ='Ratio Calculations'!N117 -> 1.1892882 | AP33: ='Ratio Calculations'!O117 -> 1.08042 | AQ33: ='Ratio Calculations'!P117 -> 0.80673753 | AR33: ='Ratio Calculations'!Q117 -> 0.94599572 | AS33: ='Ratio Calculations'!R117 -> 0.73675864
N34: ='Ratio Calculations'!N147 -> 0.23443735 | O34: ='Ratio Calculations'!O147 -> 0.19301814 | P34: ='Ratio Calculations'!P147 -> 0.17170724 | Q34: ='Ratio Calculations'!Q147 -> 0.1183425 | R34: ='Ratio Calculations'!R147 -> 0.070259597
AN35: ='Ratio Calculations'!B120 -> Debt to EBITDA
N36: ='Ratio Calculations'!B150 -> EBITDA Growth | AN36: 2020 | AO36: 2021 | AP36: 2022 | AQ36: 2023 | AR36: 2024 | AS36: 2025
N37: 2021 | O37: 2022 | P37: 2023 | Q37: 2024 | R37: 2025 | AN37: ='Ratio Calculations'!M120 -> 2.3843462 | AO37: ='Ratio Calculations'!N120 -> 1.7173036 | AP37: ='Ratio Calculations'!O120 -> 1.585345 | AQ37: ='Ratio Calculations'!P120 -> 1.0866405 | AR37: ='Ratio Calculations'!Q120 -> 1.3121359 | AS37: ='Ratio Calculations'!R120 -> 1.040614
N38: ='Ratio Calculations'!N150 -> 0.3401516 | O38: ='Ratio Calculations'!O150 -> 0.15810228 | P38: ='Ratio Calculations'!P150 -> 0.28533209 | Q38: ='Ratio Calculations'!Q150 -> 0.12056724 | R38: ='Ratio Calculations'!R150 -> 0.084995741
AN39: ='Ratio Calculations'!B132 -> Current
N40: ='Ratio Calculations'!B156 -> Net Income Growth | AN40: 2020 | AO40: 2021 | AP40: 2022 | AQ40: 2023 | AR40: 2024 | AS40: 2025
N41: 2021 | O41: 2022 | P41: 2023 | Q41: 2024 | R41: 2025 | AN41: ='Ratio Calculations'!M132 -> 1.3323978 | AO41: ='Ratio Calculations'!N132 -> 1.5358353 | AP41: ='Ratio Calculations'!O132 -> 1.3568797 | AQ41: ='Ratio Calculations'!P132 -> 1.4249938 | AR41: ='Ratio Calculations'!Q132 -> 1.4400503 | AS41: ='Ratio Calculations'!R132 -> 1.504074
N42: ='Ratio Calculations'!N156 -> 0.36830903 | O42: ='Ratio Calculations'!O156 -> 0.12741977 | P42: ='Ratio Calculations'!P156 -> 0.33872568 | Q42: ='Ratio Calculations'!Q156 -> 0.2134912 | R42: ='Ratio Calculations'!R156 -> 0.048234729
AN43: ='Ratio Calculations'!B135 -> Quick
N44: ='Ratio Calculations'!B159 -> Total Asset Growth | AN44: 2020 | AO44: 2021 | AP44: 2022 | AQ44: 2023 | AR44: 2024 | AS44: 2025
N45: 2021 | O45: 2022 | P45: 2023 | Q45: 2024 | R45: 2025 | AN45: ='Ratio Calculations'!M135 -> 1.1328697 | AO45: ='Ratio Calculations'!N135 -> 1.289015 | AP45: ='Ratio Calculations'!O135 -> 1.1252713 | AQ45: ='Ratio Calculations'!P135 -> 1.085901 | AR45: ='Ratio Calculations'!Q135 -> 1.1278821 | AS45: ='Ratio Calculations'!R135 -> 1.1567969
N46: ='Ratio Calculations'!N159 -> 0.096048145 | O46: ='Ratio Calculations'!O159 -> 0.13146607 | P46: ='Ratio Calculations'!P159 -> 0.036762234 | Q46: ='Ratio Calculations'!Q159 -> 0.17957744 | R46: ='Ratio Calculations'!R159 -> 0.013815308
AN47: ='Ratio Calculations'!B138 -> Interest Coverage
...

Sheet Profitability
J1: by/ m.salama
B3: Profitability and Return Ratios
B5: All figures in EUR thousand | D5: 2020 | E5: 2021 | F5: 2022 | G5: 2023 | H5: 2024 | I5: 2025 | J5: Average
B8: Return on Equity | D8: ='Ratio Calculations'!M8 -> 0.34030776 | E8: ='Ratio Calculations'!N8 -> 0.37674323 | F8: ='Ratio Calculations'!O8 -> 0.36092169 | G8: ='Ratio Calculations'!P8 -> 0.40951214 | H8: ='Ratio Calculations'!Q8 -> 0.43065495 | I8: ='Ratio Calculations'!R8 -> 0.40858759 | J8: =IFERROR(AVERAGE(D8:I8),0) -> 0.38778789
B9: Average | D9: =$J$8 -> 0.38778789 | E9: =$J$8 -> 0.38778789 | F9: =$J$8 -> 0.38778789 | G9: =$J$8 -> 0.38778789 | H9: =$J$8 -> 0.38778789 | I9: =$J$8 -> 0.38778789
B11: Gross Margin | D11: ='Ratio Calculations'!M20 -> 0.57558927 | E11: ='Ratio Calculations'!N20 -> 0.5667146 | F11: ='Ratio Calculations'!O20 -> 0.53111189 | G11: ='Ratio Calculations'!P20 -> 0.54679953 | H11: ='Ratio Calculations'!Q20 -> 0.54620403 | I11: ='Ratio Calculations'!R20 -> 0.5585867 | J11: =IFERROR(AVERAGE(D11:I11),0) -> 0.55416767
B12: Average | D12: =J11 -> 0.55416767 | E12: =$J$11 -> 0.55416767 | F12: =$J$11 -> 0.55416767 | G12: =$J$11 -> 0.55416767 | H12: =$J$11 -> 0.55416767 | I12: =$J$11 -> 0.55416767
B14: EBITDA Margin | D14: ='Ratio Calculations'!M29 -> 0.33029866 | E14: ='Ratio Calculations'!N29 -> 0.35858464 | F14: ='Ratio Calculations'!O29 -> 0.34809001 | G14: ='Ratio Calculations'!P29 -> 0.3818456 | H14: ='Ratio Calculations'!Q29 -> 0.38260522 | I14: ='Ratio Calculations'!R29 -> 0.38787321 | J14: =IFERROR(AVERAGE(D14:I14),0) -> 0.36488289
B15: Average | D15: =J14 -> 0.36488289 | E15: =$J$14 -> 0.36488289 | F15: =$J$14 -> 0.36488289 | G15: =$J$14 -> 0.36488289 | H15: =$J$14 -> 0.36488289 | I15: =$J$14 -> 0.36488289
B17: EBIT Margin | D17: ='Ratio Calculations'!M36 -> 0.20698568 | E17: ='Ratio Calculations'!N36 -> 0.251818 | F17: ='Ratio Calculations'!O36 -> 0.2408873 | G17: ='Ratio Calculations'!P36 -> 0.27090946 | H17: ='Ratio Calculations'!Q36 -> 0.28273849 | I17: ='Ratio Calculations'!R36 -> 0.29523978 | J17: =IFERROR(AVERAGE(D17:I17),0) -> 0.25809645
B18: Average | D18: =J17 -> 0.25809645 | E18: =$J$17 -> 0.25809645 | F18: =$J$17 -> 0.25809645 | G18: =$J$17 -> 0.25809645 | H18: =$J$17 -> 0.25809645 | I18: =$J$17 -> 0.25809645
B20: Net Profit Margin | D20: ='Ratio Calculations'!M51 -> 0.17598756 | E20: ='Ratio Calculations'!N51 -> 0.19507298 | F20: ='Ratio Calculations'!O51 -> 0.18434685 | G20: ='Ratio Calculations'!P51 -> 0.21062416 | H20: ='Ratio Calculations'!Q51 -> 0.22854409 | I20: ='Ratio Calculations'!R51 -> 0.22384088 | J20: =IFERROR(AVERAGE(D20:I20),0) -> 0.20306942
B21: Average | D21: =J20 -> 0.20306942 | E21: =$J$20 -> 0.20306942 | F21: =$J$20 -> 0.20306942 | G21: =$J$20 -> 0.20306942 | H21: =$J$20 -> 0.20306942 | I21: =$J$20 -> 0.20306942
B25: Charts

Sheet Utilization
J1: by/ m.salama
B3: Asset Utilization Ratios
B5: All figures in EUR thousand | D5: 2020 | E5: 2021 | F5: 2022 | G5: 2023 | H5: 2024 | I5: 2025 | J5: Average
B8: Asset Turnover | D8: ='Ratio Calculations'!M73 -> 0.55250144 | E8: ='Ratio Calculations'!N73 -> 0.62226137 | F8: ='Ratio Calculations'!O73 -> 0.65611256 | G8: ='Ratio Calculations'!P73 -> 0.74151219 | H8: ='Ratio Calculations'!Q73 -> 0.70301836 | I8: ='Ratio Calculations'!R73 -> 0.74215899 | J8: =IFERROR(AVERAGE(D8:I8),0) -> 0.66959415
B9: Average | D9: =$J$8 -> 0.66959415 | E9: =$J$8 -> 0.66959415 | F9: =$J$8 -> 0.66959415 | G9: =$J$8 -> 0.66959415 | H9: =$J$8 -> 0.66959415 | I9: =$J$8 -> 0.66959415
B11: Cash Days | D11: ='Ratio Calculations'!M82 -> 143.73074 | E11: ='Ratio Calculations'!N82 -> 114.87368 | F11: ='Ratio Calculations'!O82 -> 99.494326 | G11: ='Ratio Calculations'!P82 -> 68.595151 | H11: ='Ratio Calculations'!Q82 -> 95.243332 | I11: ='Ratio Calculations'!R82 -> 74.969481 | J11: =IFERROR(AVERAGE(D11:I11),0) -> 99.484452
B12: Average | D12: =J11 -> 99.484452 | E12: =$J$11 -> 99.484452 | F12: =$J$11 -> 99.484452 | G12: =$J$11 -> 99.484452 | H12: =$J$11 -> 99.484452 | I12: =$J$11 -> 99.484452
B14: A/R Days | D14: ='Ratio Calculations'!M88 -> 19.439012 | E14: ='Ratio Calculations'!N88 -> 15.810507 | F14: ='Ratio Calculations'!O88 -> 16.649044 | G14: ='Ratio Calculations'!P88 -> 15.980128 | H14: ='Ratio Calculations'!Q88 -> 19.088749 | I14: ='Ratio Calculations'!R88 -> 18.405822 | J14: =IFERROR(AVERAGE(D14:I14),0) -> 17.562211
B15: Average | D15: =J14 -> 17.562211 | E15: =$J$14 -> 17.562211 | F15: =$J$14 -> 17.562211 | G15: =$J$14 -> 17.562211 | H15: =$J$14 -> 17.562211 | I15: =$J$14 -> 17.562211
B17: Inventory Days | D17: ='Ratio Calculations'!M94 -> 114.49769 | E17: ='Ratio Calculations'!N94 -> 106.62425 | F17: ='Ratio Calculations'!O94 -> 103.0728 | G17: ='Ratio Calculations'!P94 -> 127.95619 | H17: ='Ratio Calculations'!Q94 -> 131.09278 | I17: ='Ratio Calculations'!R94 -> 128.89804 | J17: =IFERROR(AVERAGE(D17:I17),0) -> 118.69029
B18: Average | D18: =$J$17 -> 118.69029 | E18: =$J$17 -> 118.69029 | F18: =$J$17 -> 118.69029 | G18: =$J$17 -> 118.69029 | H18: =$J$17 -> 118.69029 | I18: =$J$17 -> 118.69029
B20: A/P Days | D20: ='Ratio Calculations'!M100 -> 177.4343 | E20: ='Ratio Calculations'!M100 -> 177.4343 | F20: ='Ratio Calculations'!N100 -> 157.3662 | G20: ='Ratio Calculations'!O100 -> 137.95269 | H20: ='Ratio Calculations'!P100 -> 125.53416 | I20: ='Ratio Calculations'!Q100 -> 113.9216 | J20: =IFERROR(AVERAGE(E20:I20),0) -> 142.44179
B21: Average | D21: =J20 -> 142.44179 | E21: =$J$20 -> 142.44179 | F21: =$J$20 -> 142.44179 | G21: =$J$20 -> 142.44179 | H21: =$J$20 -> 142.44179 | I21: =$J$20 -> 142.44179
B23: Cash Conversion Cycle | D23: ='Ratio Calculations'!M103 -> -43.497594 | E23: ='Ratio Calculations'!N103 -> -34.931451 | F23: ='Ratio Calculations'!O103 -> -18.230848 | G23: ='Ratio Calculations'!P103 -> 18.402154 | H23: ='Ratio Calculations'!Q103 -> 36.259926 | I23: ='Ratio Calculations'!R103 -> 49.955931 | J23: =IFERROR(AVERAGE(D23:I23),0) -> 1.3263531
B24: Average | D24: =J23 -> 1.3263531 | E24: =$J$23 -> 1.3263531 | F24: =$J$23 -> 1.3263531 | G24: =$J$23 -> 1.3263531 | H24: =$J$23 -> 1.3263531 | I24: =$J$23 -> 1.3263531
B28: Asset Utilization Ratios Charts

Sheet Leverage
J1: by/ m.salama
B3: Leverage Ratios
B5: All figures in EUR thousand | D5: 2020 | E5: 2021 | F5: 2022 | G5: 2023 | H5: 2024 | I5: 2025 | J5: Average
B8: Debt to Equity | D8: ='Ratio Calculations'!M117 -> 1.5228811 | E8: ='Ratio Calculations'!N117 -> 1.1892882 | F8: ='Ratio Calculations'!O117 -> 1.08042 | G8: ='Ratio Calculations'!P117 -> 0.80673753 | H8: ='Ratio Calculations'!Q117 -> 0.94599572 | I8: ='Ratio Calculations'!R117 -> 0.73675864 | J8: =IFERROR(AVERAGE(D8:I8),0) -> 1.0470135
B9: Average | D9: =$J$8 -> 1.0470135 | E9: =$J$8 -> 1.0470135 | F9: =$J$8 -> 1.0470135 | G9: =$J$8 -> 1.0470135 | H9: =$J$8 -> 1.0470135 | I9: =$J$8 -> 1.0470135
B11: Debt to EBITDA | D11: ='Ratio Calculations'!M120 -> 2.3843462 | E11: ='Ratio Calculations'!N120 -> 1.7173036 | F11: ='Ratio Calculations'!O120 -> 1.585345 | G11: ='Ratio Calculations'!P120 -> 1.0866405 | H11: ='Ratio Calculations'!Q120 -> 1.3121359 | I11: ='Ratio Calculations'!R120 -> 1.040614 | J11: =IFERROR(AVERAGE(D11:I11),0) -> 1.5210642
B12: Average | D12: =J11 -> 1.5210642 | E12: =$J$11 -> 1.5210642 | F12: =$J$11 -> 1.5210642 | G12: =$J$11 -> 1.5210642 | H12: =$J$11 -> 1.5210642 | I12: =$J$11 -> 1.5210642
B35: Liquidity Ratios
B38: All figures in EUR thousand | D38: 2020 | E38: 2021 | F38: 2022 | G38: 2023 | H38: 2024 | I38: 2025 | J38: Average
B41: Current | D41: ='Ratio Calculations'!M132 -> 1.3323978 | E41: ='Ratio Calculations'!N132 -> 1.5358353 | F41: ='Ratio Calculations'!O132 -> 1.3568797 | G41: ='Ratio Calculations'!P132 -> 1.4249938 | H41: ='Ratio Calculations'!Q132 -> 1.4400503 | I41: ='Ratio Calculations'!R132 -> 1.504074 | J41: =IFERROR(AVERAGE(D41:I41),0) -> 1.4323718
B42: Average | D42: =$J$41 -> 1.4323718 | E42: =$J$41 -> 1.4323718 | F42: =$J$41 -> 1.4323718 | G42: =$J$41 -> 1.4323718 | H42: =$J$41 -> 1.4323718 | I42: =$J$41 -> 1.4323718
B44: Quick | D44: ='Ratio Calculations'!M135 -> 1.1328697 | E44: ='Ratio Calculations'!N135 -> 1.289015 | F44: ='Ratio Calculations'!O135 -> 1.1252713 | G44: ='Ratio Calculations'!P135 -> 1.085901 | H44: ='Ratio Calculations'!Q135 -> 1.1278821 | I44: ='Ratio Calculations'!R135 -> 1.1567969 | J44: =IFERROR(AVERAGE(D44:I44),0) -> 1.152956
B45: Average | D45: =$J$44 -> 1.152956 | E45: =$J$44 -> 1.152956 | F45: =$J$44 -> 1.152956 | G45: =$J$44 -> 1.152956 | H45: =$J$44 -> 1.152956 | I45: =$J$44 -> 1.152956

Sheet Growth
J1: by/ m.salama
B3: Growth Trends
B5: All figures in EUR thousand | D5: 2020 | E5: 2021 | F5: 2022 | G5: 2023 | H5: 2024 | I5: 2025 | J5: Average
B8: Revenue Growth | E8: ='Ratio Calculations'!N147 -> 0.23443735 | F8: ='Ratio Calculations'!O147 -> 0.19301814 | G8: ='Ratio Calculations'!P147 -> 0.17170724 | H8: ='Ratio Calculations'!Q147 -> 0.1183425 | I8: ='Ratio Calculations'!R147 -> 0.070259597 | J8: =IFERROR(AVERAGE(E8:I8),0) -> 0.15755296
B9: Average | E9: =$J$8 -> 0.15755296 | F9: =$J$8 -> 0.15755296 | G9: =$J$8 -> 0.15755296 | H9: =$J$8 -> 0.15755296 | I9: =$J$8 -> 0.15755296
B11: EBITDA Growth | E11: ='Ratio Calculations'!N150 -> 0.3401516 | F11: ='Ratio Calculations'!O150 -> 0.15810228 | G11: ='Ratio Calculations'!P150 -> 0.28533209 | H11: ='Ratio Calculations'!Q150 -> 0.12056724 | I11: ='Ratio Calculations'!R150 -> 0.084995741 | J11: =IFERROR(AVERAGE(E11:I11),0) -> 0.19782979
B12: Average | E12: =$J$11 -> 0.19782979 | F12: =$J$11 -> 0.19782979 | G12: =$J$11 -> 0.19782979 | H12: =$J$11 -> 0.19782979 | I12: =$J$11 -> 0.19782979
B14: Net Income Growth | E14: ='Ratio Calculations'!N156 -> 0.36830903 | F14: ='Ratio Calculations'!O156 -> 0.12741977 | G14: ='Ratio Calculations'!P156 -> 0.33872568 | H14: ='Ratio Calculations'!Q156 -> 0.2134912 | I14: ='Ratio Calculations'!R156 -> 0.048234729 | J14: =IFERROR(AVERAGE(E14:I14),0) -> 0.21923608
B15: Average | E15: =$J$14 -> 0.21923608 | F15: =$J$14 -> 0.21923608 | G15: =$J$14 -> 0.21923608 | H15: =$J$14 -> 0.21923608 | I15: =$J$14 -> 0.21923608
B17: Total Asset Growth | E17: ='Ratio Calculations'!N159 -> 0.096048145 | F17: ='Ratio Calculations'!O159 -> 0.13146607 | G17: ='Ratio Calculations'!P159 -> 0.036762234 | H17: ='Ratio Calculations'!Q159 -> 0.17957744 | I17: ='Ratio Calculations'!R159 -> 0.013815308 | J17: =IFERROR(AVERAGE(E17:I17),0) -> 0.091533839
B18: Average | E18: =$J$17 -> 0.091533839 | F18: =$J$17 -> 0.091533839 | G18: =$J$17 -> 0.091533839 | H18: =$J$17 -> 0.091533839 | I18: =$J$17 -> 0.091533839
B22: Charts
